<?xml version="1.0"?>
<robot xmlns:xacro="http://www.ros.org/wiki/xacro">

  <xacro:include filename="$(find batbot_description)/urdf/batbot/common_inertia.xacro" />

  <xacro:macro name="wheel_xacro" params="wheel_name length radius xyz">

    <link name="${wheel_name}_wheel_link">
      <visual>
        <origin xyz="0 0 0" rpy="${pi/2} 0 0" />
        <geometry>
          <cylinder length="${length}" radius="${radius}" />
        </geometry>
        <material name="black" />
      </visual>
      <collision>
        <origin xyz="0 0 0" rpy="${pi/2} 0 0" />
        <geometry>
          <cylinder length="${length}" radius="${radius}" />
        </geometry>
        <material name="black" />
      </collision>
      <xacro:cylinder_inertia m="0.1" h="${length}" r="${radius}" />
    </link>

    <joint name="${wheel_name}_wheel_joint" type="continuous">
      <parent link="base_link" />
      <child link="${wheel_name}_wheel_link" />
      <origin xyz="${xyz}" />
      <axis xyz="0 1 0" />
    </joint>

  </xacro:macro>
</robot>